Workbook

Sheet Front page
F10: TAMIL NADU VETERINARY AND ANIMAL SCIENCEAS UNIVERSITY
F11: VETERINARY COLLEGE AND RESEARCH INSTITUTE, NAMAKKAL
F12: DEPARTMENT OF ANIMAL HUSBANDRY ECONOMICS
H13: PROJECT REPORT ON DAIRY FARMING
F15: Title of the Project: | G15: Development of specialized computer software to assist veterinary professionals in creating bankable livestock and poultry farming project report
H16: Under Tamil Nadu GovernmentScheme on
I17: "Students - Entrepreneurs - Industrialists Conclave: Showcasing, refinement and support for commersialization of the innovations of students in the field of Veterinary and Animal Sciences"
G19: Name of the Student
G20: DHARSHID VINESH, U.R. BVN 23018
G21: DHARSHIKA, K BVN 23038
G22: III PFY, B.V.Sc., & A.H., 2023-24 Batch
G24: Name of the Mentor
H25: Dr. V. Senthilkumar, M.V.Sc., Ph.D.,
H26: Professor and Head,
H27: Department of Animal Husbandry Economics
H28: Veterinary College and Reasearch Institute
H29: Namakkal 637 002

Sheet Project at a glance
C3: PROJECT REPORT ON DAIRY FARMING
C5: PROJECT AT A GLANCE
A6: 1 | B6: Name of the Farmer/Unit
A7: 2 | B7: Address of the Farmer
A8: 3 | B8: Aadhar Number (Optional)
A9: 4 | B9: Mobile Number
A10: 5 | B10: E mail Id (Optional)
A11: 6 | B11: Nature of the Farming / Activity
B12: Number of animals
A13: 7 | B13: Address location of the Farm
A14: 8 | B14: Name of the Financing Bank
A15: 9 | B15: Name of the Branch
A16: 10 | B16: PROJECT COST
B17: Capital and Machineary Investment (in Rs.) | C17: =Investment!C33 -> 1482500
B18: Working Capital (in Rs.) | C18: =Investment!C51 -> 151100
B19: Total Cost of the Project (in Rs.) | C19: =Investment!C52 -> 1633600
A20: 11 | B20: MEANS OF FINANCE
B21: Bank Loan (in Rs.) | C21: =Investment!C55 -> 1551920
B22: Margin Money (in Rs.) | C22: =Investment!C56 -> 81680
B23: Total (in Rs.) | C23: =Investment!C58 -> 571760
B24: Subsidy (in Rs.)
B25: Name of Subsidy Programme
B26: Rate of Interest (in percent / annum) | C26: ='Techno Economic Parameters'!C53 -> 11.5
B27: Repayment Period (in years) | C27: ='Techno Economic Parameters'!C54 -> 7
A28: 12 | B28: Project evaluation Values
B29: NPV | C29: ='Financial Analysis'!F15 -> 2901362.8
B30: BCR | C30: ='Financial Analysis'!F16 -> 1.9933332
B31: IRR (in per cent) | C31: ='Financial Analysis'!E28 -> 24.206612
B32: DSCR | C32: ='Financial Analysis'!E38 -> 2.6610251
A33: 13 | B33: Employment opportunities(in No. of labour)

Sheet Techno Economic Parameters
C3: PROJECT REPORT ON DAIRY FARMING
B5: TECHNO ECONOMIC PARAMETERS
B6: ANIMAL
B7: Type of Milch Animal | C7: Cow / | D7: Buffalo
B8: Name of the Breed | C8: Jersey Cross | D8: HF Cross | E8: Indigenous
B9: Unit Size (No. of Animals) | C9: 10 | D9: 5 | E9: I Batch | F9: 5 | G9: II Batch
B10: Purchase cost of Animals (Rs./Animal) | C10: 80000
B11: Average Milk Yield (Litres/day) | C11: 12
B12: Insurance Premium (in percent / animal / annum) | C12: 6
B13: Transport Charges (Rs./Animal) | C13: 1000
B15: SHED/BUILDING | E15: Standard
B16: Floor Space Requirement for Milch Animal (Sq.ft/Animal) | C16: 60 | E16: 55-70 sq.ft | F16: per cow
B17: Cost of Construction for Animal Shed (Rs./Sq.ft) | C17: 450
B18: Floor Space Requirement for Calves (Sq.ft/Calf) | C18: 30 | E18: 15-20 sq.ft | F18: per calf
B19: Cost of Construction for Calves Shed (Rs./Sq.ft) | C19: 250
B20: Floor Space Requirement for Store Room (in Sq.ft) | C20: 600
B21: Cost of Construction for Store Room (Rs./Sq.ft) | C21: 450
B23: EQUIPMENT
B24: Cost of Equipment for Feeder and Waterer (Rs./animal) | C24: 200
B25: Cost of Milking Can (in Rs.) | C25: 3000
B26: Cost of Milking Machine (in Rs.) | C26: 60000
B27: Cost of Chaff Cutter (in Rs.) | C27: 30000
B28: Cost of Brush Cutter (in Rs.) | C28: 10000
B29: Cost of Feed Making Machinery (in Rs.) | C29: 0
B30: Cost of Milk Processing Machinery (in Rs.) | C30: 0
B31: Cost of Motor for irrigation facilities (in Rs.) | C31: 0
B32: Cost of Sprinkler and Fogger | C32: 0
B33: Cost of Computers (in Rs.) | C33: 0
B34: Cost of CCTV (in Rs.) | C34: 0
B36: OTHER INFRASTRUCTURE
B37: Floor Space Requirement for Labour Quarters (in Sq.ft) | C37: 0
B38: Cost of Construction for Labour Quarters (Rs./Sq.ft) | C38: 0
B39: Cost of Establishment of Overhead Tank (in Rs.) | C39: 0
B40: Cost of Fencing (in Rs.) | C40: 0
B41: Land leveling Charges (in Rs.) | C41: 0
B42: Digging of Borewell (in Rs.) | C42: 0
B43: Floor Space Requirement for Feed Mill (in Sq.ft) | C43: 0
B44: Cost of Construction for Feed Mill (Rs./Sq.ft) | C44: 0
B45: Floor Space Requirement for Milk Processing Unit (in Sq.ft) | C45: 0
B46: Cost of Construction for Milk Processing Unit (Rs./Sq.ft) | C46: 0
...

Sheet Investment
B2: INVESTMENT OF THE PROJECT
B5: CAPITAL/FIXED INVESTMENT | E5: Fixed Investment : It refers to buying /constructing long term physical assets such as animals, sheds and equipments.
B6: Cost of Milch Animals | C6: ='Techno Economic Parameters'!C9*'Techno Economic Parameters'!C10 -> 800000
B7: Cost of Construction for Animal Shed | C7: =ROUNDDOWN(('Techno Economic Parameters'!C9*'Techno Economic Parameters'!C16*'Techno Economic Parameters'!C17),-2) -> 270000
B8: Cost of Construction for Calves pen | C8: ='Techno Economic Parameters'!C9/2*'Techno Economic Parameters'!C18*'Techno Economic Parameters'!C19 -> 37500
B9: Cost of Construction for Store Room | C9: ='Techno Economic Parameters'!C20*'Techno Economic Parameters'!C21 -> 270000
B10: Cost of Construction for Labour Quarters | C10: ='Techno Economic Parameters'!C37*'Techno Economic Parameters'!C38 -> 0
B11: Cost of Equipment for Feeder and Waterer | C11: ='Techno Economic Parameters'!C9*'Techno Economic Parameters'!C24 -> 2000
B12: Cost of Milking Can | C12: ='Techno Economic Parameters'!C25 -> 3000
B13: Cost of Milking Machine | C13: ='Techno Economic Parameters'!C26 -> 60000
B14: Cost of Chaff Cutter | C14: ='Techno Economic Parameters'!C27 -> 30000
B15: Cost of Brush Cutter | C15: ='Techno Economic Parameters'!C28 -> 10000
B16: Cost of Feed Making Machinery | C16: ='Techno Economic Parameters'!C29 -> 0
B17: Cost of Milk Processing Machinery | C17: ='Techno Economic Parameters'!C30 -> 0
B18: Cost of Motor for irrigation facilities | C18: ='Techno Economic Parameters'!C31 -> 0
B19: Cost of Sprinkler and Fogger | C19: ='Techno Economic Parameters'!C32 -> 0
B20: Cost of Establishment of Overhead Tank | C20: ='Techno Economic Parameters'!C39 -> 0
B21: Cost of Fencing | C21: ='Techno Economic Parameters'!C40 -> 0
B22: Land leveling Charges | C22: ='Techno Economic Parameters'!C41 -> 0
B23: Digging of Borewell | C23: ='Techno Economic Parameters'!C42 -> 0
B24: Cost of Construction for Feed Mill | C24: ='Techno Economic Parameters'!C43*'Techno Economic Parameters'!C44 -> 0
B25: Cost of Construction for Milk Processing Unit | C25: ='Techno Economic Parameters'!C45*'Techno Economic Parameters'!C46 -> 0
B26: Cost for Establishment of Bio Gas Unit | C26: ='Techno Economic Parameters'!C47*'Techno Economic Parameters'!C48 -> 0
B27: Cost for Establishment of Vermicompost Unit | C27: ='Techno Economic Parameters'!C48 -> 0
B28: Cost for Establishment of Silage Making Unit | C28: ='Techno Economic Parameters'!C49 -> 0
B29: Cost of Vehicle | C29: =(('Techno Economic Parameters'!C58*'Techno Economic Parameters'!C59)+('Techno Economic Parameters'!C60*'Techno Economic Parameters'!E62)) -> 0
B30: Cost of Computers | C30: ='Techno Economic Parameters'!C33 -> 0
B31: Cost of CCTV | C31: ='Techno Economic Parameters'!C34 -> 0
B33: Total Capital Investment | C33: =ROUNDDOWN(SUM(C6:C32),-2) -> 1482500
B35: WORKING CAPITAL | E35: Working Capital: It represents the funds required to operate day to day farming expenses up to the certain period of receiving income.
B36: Insurance Premium | C36: =C6*'Techno Economic Parameters'!C12% -> 48000
B37: Transport Charges | C37: ='Techno Economic Parameters'!C9*'Techno Economic Parameters'!C13 -> 10000
B38: Cost of Concentrate Feed | C38: ='Techno Economic Parameters'!D9*'Techno Economic Parameters'!C66*'Techno Economic Parameters'!C68*90 -> 43200
B39: Cost of Dry Fodder | C39: ='Techno Economic Parameters'!D9*'Techno Economic Parameters'!C69*'Techno Economic Parameters'!C70*90 -> 5400
B40: Cost of Green Fodder | C40: ='Techno Economic Parameters'!C71*'Techno Economic Parameters'!C72 -> 10000
B41: Labour Wages | C41: =((('Techno Economic Parameters'!C86*'Techno Economic Parameters'!C87)+('Techno Economic Parameters'!C88*'Techno Economic Parameters'!C89)+('Techno Economic Parameters'!C90*'Techno Economic Parameters'!C91)+('Techno Economic Parameters'!C92*'Techno Economic Parameters'!C93))*3) -> 30000
B42: Veterinary Expenses | C42: ='Techno Economic Parameters'!C74*'Techno Economic Parameters'!D9 -> 2500
B43: Electricity Expenses | C43: ='Techno Economic Parameters'!C75*3 -> 1500
B44: Fuel Expenses | C44: ='Techno Economic Parameters'!C76*3 -> 0
B45: Miscellaneous Expenses | C45: ='Techno Economic Parameters'!C79*'Techno Economic Parameters'!D9 -> 500
...

Sheet Production Chart
C2: PRODUCTION CHART
C4: Lactation Yield (in Litres)
C6: I Year | D6: II Year | E6: III Year | F6: IV Year | G6: V Year | H6: VI Year | I6: VII Year
B7: First Batch (Milk Yield Quantity in Litres) | C7: ='Techno Economic Parameters'!$D$9*'Techno Economic Parameters'!$C$64*'Techno Economic Parameters'!$C$11 -> 18000 | D7: ='Techno Economic Parameters'!$D$9*'Techno Economic Parameters'!$C$64*'Techno Economic Parameters'!$C$11 -> 18000 | E7: ='Techno Economic Parameters'!$D$9*'Techno Economic Parameters'!$C$64*'Techno Economic Parameters'!$C$11 -> 18000 | F7: ='Techno Economic Parameters'!$D$9*'Techno Economic Parameters'!$C$64*'Techno Economic Parameters'!$C$11 -> 18000 | G7: ='Techno Economic Parameters'!$D$9*'Techno Economic Parameters'!$C$64*'Techno Economic Parameters'!$C$11 -> 18000 | H7: ='Techno Economic Parameters'!$D$9*'Techno Economic Parameters'!$C$64*'Techno Economic Parameters'!$C$11 -> 18000 | I7: ='Techno Economic Parameters'!$D$9*'Techno Economic Parameters'!$C$64*'Techno Economic Parameters'!$C$11 -> 18000
B8: Second Batch (Milk Yield Quantity in Litres) | C8: ='Techno Economic Parameters'!D9*180*'Techno Economic Parameters'!C11 -> 10800 | D8: ='Techno Economic Parameters'!$C$64*'Techno Economic Parameters'!$F$9*'Techno Economic Parameters'!$C$11 -> 18000 | E8: ='Techno Economic Parameters'!$C$64*'Techno Economic Parameters'!$F$9*'Techno Economic Parameters'!$C$11 -> 18000 | F8: ='Techno Economic Parameters'!$C$64*'Techno Economic Parameters'!$F$9*'Techno Economic Parameters'!$C$11 -> 18000 | G8: ='Techno Economic Parameters'!$C$64*'Techno Economic Parameters'!$F$9*'Techno Economic Parameters'!$C$11 -> 18000 | H8: ='Techno Economic Parameters'!$C$64*'Techno Economic Parameters'!$F$9*'Techno Economic Parameters'!$C$11 -> 18000 | I8: ='Techno Economic Parameters'!$C$64*'Techno Economic Parameters'!$F$9*'Techno Economic Parameters'!$C$11 -> 18000
B10: Total Milk Yield in Litres | C10: =SUM(C7:C9) -> 28800 | D10: =SUM(D7:D9) -> 36000 | E10: =SUM(E7:E9) -> 36000 | F10: =SUM(F7:F9) -> 36000 | G10: =SUM(G7:G9) -> 36000 | H10: =SUM(H7:H9) -> 36000 | I10: =SUM(I7:I9) -> 36000

Sheet Expenditure Income 
C2: EXPENDITURE INCOME STATEMENT
C4: I Year | D4: II Year | E4: III Year | F4: IV Year | G4: V Year | H4: VI Year | I4: VII Year
B5: Expenditure
B6: Insurance Premium | C6: =(('Techno Economic Parameters'!$C$9*'Techno Economic Parameters'!$C$10)*'Techno Economic Parameters'!$C$12%) -> 48000 | D6: =(('Techno Economic Parameters'!$C$9*'Techno Economic Parameters'!$C$10)*'Techno Economic Parameters'!$C$12%) -> 48000 | E6: =(('Techno Economic Parameters'!$C$9*'Techno Economic Parameters'!$C$10)*'Techno Economic Parameters'!$C$12%) -> 48000 | F6: =(('Techno Economic Parameters'!$C$9*'Techno Economic Parameters'!$C$10)*'Techno Economic Parameters'!$C$12%) -> 48000 | G6: =(('Techno Economic Parameters'!$C$9*'Techno Economic Parameters'!$C$10)*'Techno Economic Parameters'!$C$12%) -> 48000 | H6: =(('Techno Economic Parameters'!$C$9*'Techno Economic Parameters'!$C$10)*'Techno Economic Parameters'!$C$12%) -> 48000 | I6: =(('Techno Economic Parameters'!$C$9*'Techno Economic Parameters'!$C$10)*'Techno Economic Parameters'!$C$12%) -> 48000
B7: Transport Charges | C7: ='Techno Economic Parameters'!C9*'Techno Economic Parameters'!C13 -> 10000 | D7: 0 | E7: 0 | F7: 0 | G7: 0 | H7: 0 | I7: 0
B8: Cost of Concentrate Feed | C8: =(('Techno Economic Parameters'!D9*'Techno Economic Parameters'!C64*'Techno Economic Parameters'!C66*'Techno Economic Parameters'!C68)+('Techno Economic Parameters'!F9*180*'Techno Economic Parameters'!C66*'Techno Economic Parameters'!C68)+('Techno Economic Parameters'!D9*'Techno Economic Parameters'!C65*'Techno Economic Parameters'!C68)) -> 238200 | D8: =(('Techno Economic Parameters'!$C$9*'Techno Economic Parameters'!$C$64*'Techno Economic Parameters'!$C$66*'Techno Economic Parameters'!$C$68)+('Techno Economic Parameters'!$C$9*'Techno Economic Parameters'!$C$67*'Techno Economic Parameters'!$C$68)) -> 288480 | E8: =(('Techno Economic Parameters'!$C$9*'Techno Economic Parameters'!$C$64*'Techno Economic Parameters'!$C$66*'Techno Economic Parameters'!$C$68)+('Techno Economic Parameters'!$C$9*'Techno Economic Parameters'!$C$67*'Techno Economic Parameters'!$C$68)) -> 288480 | F8: =(('Techno Economic Parameters'!$C$9*'Techno Economic Parameters'!$C$64*'Techno Economic Parameters'!$C$66*'Techno Economic Parameters'!$C$68)+('Techno Economic Parameters'!$C$9*'Techno Economic Parameters'!$C$67*'Techno Economic Parameters'!$C$68)) -> 288480 | G8: =(('Techno Economic Parameters'!$C$9*'Techno Economic Parameters'!$C$64*'Techno Economic Parameters'!$C$66*'Techno Economic Parameters'!$C$68)+('Techno Economic Parameters'!$C$9*'Techno Economic Parameters'!$C$67*'Techno Economic Parameters'!$C$68)) -> 288480 | H8: =(('Techno Economic Parameters'!$C$9*'Techno Economic Parameters'!$C$64*'Techno Economic Parameters'!$C$66*'Techno Economic Parameters'!$C$68)+('Techno Economic Parameters'!$C$9*'Techno Economic Parameters'!$C$67*'Techno Economic Parameters'!$C$68)) -> 288480 | I8: =(('Techno Economic Parameters'!$C$9*'Techno Economic Parameters'!$C$64*'Techno Economic Parameters'!$C$66*'Techno Economic Parameters'!$C$68)+('Techno Economic Parameters'!$C$9*'Techno Economic Parameters'!$C$67*'Techno Economic Parameters'!$C$68)) -> 288480
B9: Cost of Dry Fodder | C9: ='Techno Economic Parameters'!$C$9*365*'Techno Economic Parameters'!$C$69*'Techno Economic Parameters'!$C$70 -> 43800 | D9: ='Techno Economic Parameters'!$C$9*365*'Techno Economic Parameters'!$C$69*'Techno Economic Parameters'!$C$70 -> 43800 | E9: ='Techno Economic Parameters'!$C$9*365*'Techno Economic Parameters'!$C$69*'Techno Economic Parameters'!$C$70 -> 43800 | F9: ='Techno Economic Parameters'!$C$9*365*'Techno Economic Parameters'!$C$69*'Techno Economic Parameters'!$C$70 -> 43800 | G9: ='Techno Economic Parameters'!$C$9*365*'Techno Economic Parameters'!$C$69*'Techno Economic Parameters'!$C$70 -> 43800 | H9: ='Techno Economic Parameters'!$C$9*365*'Techno Economic Parameters'!$C$69*'Techno Economic Parameters'!$C$70 -> 43800 | I9: ='Techno Economic Parameters'!$C$9*365*'Techno Economic Parameters'!$C$69*'Techno Economic Parameters'!$C$70 -> 43800
B10: Cost of Green Fodder | C10: ='Techno Economic Parameters'!C71*'Techno Economic Parameters'!C72 -> 10000 | D10: ='Techno Economic Parameters'!$C$71*'Techno Economic Parameters'!$C$73 -> 6000 | E10: ='Techno Economic Parameters'!$C$71*'Techno Economic Parameters'!$C$73 -> 6000 | F10: ='Techno Economic Parameters'!$C$71*'Techno Economic Parameters'!$C$73 -> 6000 | G10: ='Techno Economic Parameters'!$C$71*'Techno Economic Parameters'!$C$73 -> 6000 | H10: ='Techno Economic Parameters'!$C$71*'Techno Economic Parameters'!$C$73 -> 6000 | I10: ='Techno Economic Parameters'!$C$71*'Techno Economic Parameters'!$C$73 -> 6000
B11: Labour Wages | C11: =((('Techno Economic Parameters'!$C$86*'Techno Economic Parameters'!$C$87)+('Techno Economic Parameters'!$C$88*'Techno Economic Parameters'!$C$89)+('Techno Economic Parameters'!$C$90*'Techno Economic Parameters'!$C$91)+('Techno Economic Parameters'!$C$92*'Techno Economic Parameters'!$C$93))*12) -> 120000 | D11: =((('Techno Economic Parameters'!$C$86*'Techno Economic Parameters'!$C$87)+('Techno Economic Parameters'!$C$88*'Techno Economic Parameters'!$C$89)+('Techno Economic Parameters'!$C$90*'Techno Economic Parameters'!$C$91)+('Techno Economic Parameters'!$C$92*'Techno Economic Parameters'!$C$93))*12) -> 120000 | E11: =((('Techno Economic Parameters'!$C$86*'Techno Economic Parameters'!$C$87)+('Techno Economic Parameters'!$C$88*'Techno Economic Parameters'!$C$89)+('Techno Economic Parameters'!$C$90*'Techno Economic Parameters'!$C$91)+('Techno Economic Parameters'!$C$92*'Techno Economic Parameters'!$C$93))*12) -> 120000 | F11: =((('Techno Economic Parameters'!$C$86*'Techno Economic Parameters'!$C$87)+('Techno Economic Parameters'!$C$88*'Techno Economic Parameters'!$C$89)+('Techno Economic Parameters'!$C$90*'Techno Economic Parameters'!$C$91)+('Techno Economic Parameters'!$C$92*'Techno Economic Parameters'!$C$93))*12) -> 120000 | G11: =((('Techno Economic Parameters'!$C$86*'Techno Economic Parameters'!$C$87)+('Techno Economic Parameters'!$C$88*'Techno Economic Parameters'!$C$89)+('Techno Economic Parameters'!$C$90*'Techno Economic Parameters'!$C$91)+('Techno Economic Parameters'!$C$92*'Techno Economic Parameters'!$C$93))*12) -> 120000 | H11: =((('Techno Economic Parameters'!$C$86*'Techno Economic Parameters'!$C$87)+('Techno Economic Parameters'!$C$88*'Techno Economic Parameters'!$C$89)+('Techno Economic Parameters'!$C$90*'Techno Economic Parameters'!$C$91)+('Techno Economic Parameters'!$C$92*'Techno Economic Parameters'!$C$93))*12) -> 120000 | I11: =((('Techno Economic Parameters'!$C$86*'Techno Economic Parameters'!$C$87)+('Techno Economic Parameters'!$C$88*'Techno Economic Parameters'!$C$89)+('Techno Economic Parameters'!$C$90*'Techno Economic Parameters'!$C$91)+('Techno Economic Parameters'!$C$92*'Techno Economic Parameters'!$C$93))*12) -> 120000
B12: Veterinary Expenses | C12: ='Techno Economic Parameters'!$C$74*'Techno Economic Parameters'!$C$9 -> 5000 | D12: ='Techno Economic Parameters'!$C$74*'Techno Economic Parameters'!$C$9 -> 5000 | E12: ='Techno Economic Parameters'!$C$74*'Techno Economic Parameters'!$C$9 -> 5000 | F12: ='Techno Economic Parameters'!$C$74*'Techno Economic Parameters'!$C$9 -> 5000 | G12: ='Techno Economic Parameters'!$C$74*'Techno Economic Parameters'!$C$9 -> 5000 | H12: ='Techno Economic Parameters'!$C$74*'Techno Economic Parameters'!$C$9 -> 5000 | I12: ='Techno Economic Parameters'!$C$74*'Techno Economic Parameters'!$C$9 -> 5000
B13: Electricity Expenses | C13: ='Techno Economic Parameters'!$C$75*12 -> 6000 | D13: ='Techno Economic Parameters'!$C$75*12 -> 6000 | E13: ='Techno Economic Parameters'!$C$75*12 -> 6000 | F13: ='Techno Economic Parameters'!$C$75*12 -> 6000 | G13: ='Techno Economic Parameters'!$C$75*12 -> 6000 | H13: ='Techno Economic Parameters'!$C$75*12 -> 6000 | I13: ='Techno Economic Parameters'!$C$75*12 -> 6000
B14: Fuel Expenses | C14: ='Techno Economic Parameters'!$C$76*12 -> 0 | D14: ='Techno Economic Parameters'!$C$76*12 -> 0 | E14: ='Techno Economic Parameters'!$C$76*12 -> 0 | F14: ='Techno Economic Parameters'!$C$76*12 -> 0 | G14: ='Techno Economic Parameters'!$C$76*12 -> 0 | H14: ='Techno Economic Parameters'!$C$76*12 -> 0 | I14: ='Techno Economic Parameters'!$C$76*12 -> 0
B15: Miscellaneous Expenses | C15: ='Techno Economic Parameters'!$C$79*'Techno Economic Parameters'!$C$9 -> 1000 | D15: ='Techno Economic Parameters'!$C$79*'Techno Economic Parameters'!$C$9 -> 1000 | E15: ='Techno Economic Parameters'!$C$79*'Techno Economic Parameters'!$C$9 -> 1000 | F15: ='Techno Economic Parameters'!$C$79*'Techno Economic Parameters'!$C$9 -> 1000 | G15: ='Techno Economic Parameters'!$C$79*'Techno Economic Parameters'!$C$9 -> 1000 | H15: ='Techno Economic Parameters'!$C$79*'Techno Economic Parameters'!$C$9 -> 1000 | I15: ='Techno Economic Parameters'!$C$79*'Techno Economic Parameters'!$C$9 -> 1000
B16: Expenses for Feed Making Unit | C16: ='Techno Economic Parameters'!$C$80 -> 0 | D16: ='Techno Economic Parameters'!$C$80 -> 0 | E16: ='Techno Economic Parameters'!$C$80 -> 0 | F16: ='Techno Economic Parameters'!$C$80 -> 0 | G16: ='Techno Economic Parameters'!$C$80 -> 0 | H16: ='Techno Economic Parameters'!$C$80 -> 0 | I16: ='Techno Economic Parameters'!$C$80 -> 0
B17: Expenses for Milk Processing Unit | C17: ='Techno Economic Parameters'!$C$81 -> 0 | D17: ='Techno Economic Parameters'!$C$81 -> 0 | E17: ='Techno Economic Parameters'!$C$81 -> 0 | F17: ='Techno Economic Parameters'!$C$81 -> 0 | G17: ='Techno Economic Parameters'!$C$81 -> 0 | H17: ='Techno Economic Parameters'!$C$81 -> 0 | I17: ='Techno Economic Parameters'!$C$81 -> 0
B18: Expenses for Vermicompost Unit | C18: ='Techno Economic Parameters'!$C$82 -> 0 | D18: ='Techno Economic Parameters'!$C$82 -> 0 | E18: ='Techno Economic Parameters'!$C$82 -> 0 | F18: ='Techno Economic Parameters'!$C$82 -> 0 | G18: ='Techno Economic Parameters'!$C$82 -> 0 | H18: ='Techno Economic Parameters'!$C$82 -> 0 | I18: ='Techno Economic Parameters'!$C$82 -> 0
B19: Expenses for Silage Making Unit | C19: ='Techno Economic Parameters'!$C$83 -> 0 | D19: ='Techno Economic Parameters'!$C$83 -> 0 | E19: ='Techno Economic Parameters'!$C$83 -> 0 | F19: ='Techno Economic Parameters'!$C$83 -> 0 | G19: ='Techno Economic Parameters'!$C$83 -> 0 | H19: ='Techno Economic Parameters'!$C$83 -> 0 | I19: ='Techno Economic Parameters'!$C$83 -> 0
B20: Interest | C20: =SUM(Repayment!E11:E22) -> 174198.28 | D20: =SUM(Repayment!E23:E34) -> 156828.02 | E20: =SUM(Repayment!E35:E46) -> 136583.07 | F20: =SUM(Repayment!E47:E58) -> 113883.21 | G20: =SUM(Repayment!E59:E70) -> 88430.78 | H20: =SUM(Repayment!E71:E82) -> 59891.99 | I20: =SUM(Repayment!E83:E94) -> 27892.64
B21: Depreciation on Building | C21: =Depreciation!C4 -> 57750 | D21: =Depreciation!C5 -> 51975 | E21: =Depreciation!C6 -> 46777.5 | F21: =Depreciation!C7 -> 42099.75 | G21: =Depreciation!C8 -> 37889.775 | H21: =Depreciation!C9 -> 34100.798 | I21: =Depreciation!C10 -> 30690.718
B22: Depreciation on Equipments | C22: =Depreciation!F4 -> 15750 | D22: =Depreciation!F5 -> 13387.5 | E22: =Depreciation!F6 -> 11379.375 | F22: =Depreciation!F7 -> 9672.4688 | G22: =Depreciation!F8 -> 8221.5984 | H22: =Depreciation!F9 -> 6988.3587 | I22: =Depreciation!F10 -> 5940.1049
B24: Total Expendiutre | C24: =SUM(C6:C20) -> 656198.28 | D24: =SUM(D6:D20) -> 675108.02 | E24: =SUM(E6:E20) -> 654863.07 | F24: =SUM(F6:F20) -> 632163.21 | G24: =SUM(G6:G20) -> 606710.78 | H24: =SUM(H6:H20) -> 578171.99 | I24: =SUM(I6:I20) -> 546172.64
B26: Income
B27: By Sale of Milk | C27: ='Production Chart'!C10*'Techno Economic Parameters'!C96 -> 1065600 | D27: ='Production Chart'!$D$10*'Techno Economic Parameters'!$C$96 -> 1332000 | E27: ='Production Chart'!$D$10*'Techno Economic Parameters'!$C$96 -> 1332000 | F27: ='Production Chart'!$D$10*'Techno Economic Parameters'!$C$96 -> 1332000 | G27: ='Production Chart'!$D$10*'Techno Economic Parameters'!$C$96 -> 1332000 | H27: ='Production Chart'!$D$10*'Techno Economic Parameters'!$C$96 -> 1332000 | I27: ='Production Chart'!$D$10*'Techno Economic Parameters'!$C$96 -> 1332000
B28: By Sale of Male Calves | C28: =(('Techno Economic Parameters'!$C$9/2)*'Techno Economic Parameters'!$C$97) -> 10000 | D28: =(('Techno Economic Parameters'!$C$9/2)*'Techno Economic Parameters'!$C$97) -> 10000 | E28: =(('Techno Economic Parameters'!$C$9/2)*'Techno Economic Parameters'!$C$97) -> 10000 | F28: =(('Techno Economic Parameters'!$C$9/2)*'Techno Economic Parameters'!$C$97) -> 10000 | G28: =(('Techno Economic Parameters'!$C$9/2)*'Techno Economic Parameters'!$C$97) -> 10000 | H28: =(('Techno Economic Parameters'!$C$9/2)*'Techno Economic Parameters'!$C$97) -> 10000 | I28: =(('Techno Economic Parameters'!$C$9/2)*'Techno Economic Parameters'!$C$97) -> 10000
B29: By Sale Value of Female Calves | C29: =(('Techno Economic Parameters'!$C$9/2)*('Techno Economic Parameters'!$C$98)) -> 25000 | D29: =(('Techno Economic Parameters'!$C$9/2)*('Techno Economic Parameters'!$C$98)) -> 25000 | E29: =(('Techno Economic Parameters'!$C$9/2)*('Techno Economic Parameters'!$C$98)) -> 25000 | F29: =(('Techno Economic Parameters'!$C$9/2)*('Techno Economic Parameters'!$C$98)) -> 25000 | G29: =(('Techno Economic Parameters'!$C$9/2)*('Techno Economic Parameters'!$C$98)) -> 25000 | H29: =(('Techno Economic Parameters'!$C$9/2)*('Techno Economic Parameters'!$C$98)) -> 25000 | I29: =(('Techno Economic Parameters'!$C$9/2)*('Techno Economic Parameters'!$C$98)) -> 25000
B30: My Sale of Mannure | C30: ='Techno Economic Parameters'!$C$99*'Techno Economic Parameters'!$C$9 -> 5000 | D30: ='Techno Economic Parameters'!$C$99*'Techno Economic Parameters'!$C$9 -> 5000 | E30: ='Techno Economic Parameters'!$C$99*'Techno Economic Parameters'!$C$9 -> 5000 | F30: ='Techno Economic Parameters'!$C$99*'Techno Economic Parameters'!$C$9 -> 5000 | G30: ='Techno Economic Parameters'!$C$99*'Techno Economic Parameters'!$C$9 -> 5000 | H30: ='Techno Economic Parameters'!$C$99*'Techno Economic Parameters'!$C$9 -> 5000 | I30: ='Techno Economic Parameters'!$C$99*'Techno Economic Parameters'!$C$9 -> 5000
B31: Income from Milk Processing Unit | C31: ='Techno Economic Parameters'!$C$101 -> 0 | D31: ='Techno Economic Parameters'!$C$101 -> 0 | E31: ='Techno Economic Parameters'!$C$101 -> 0 | F31: ='Techno Economic Parameters'!$C$101 -> 0 | G31: ='Techno Economic Parameters'!$C$101 -> 0 | H31: ='Techno Economic Parameters'!$C$101 -> 0 | I31: ='Techno Economic Parameters'!$C$101 -> 0
B32: Income from Vermicompost Unit | C32: ='Techno Economic Parameters'!$C$103 -> 0 | D32: ='Techno Economic Parameters'!$C$103 -> 0 | E32: ='Techno Economic Parameters'!$C$103 -> 0 | F32: ='Techno Economic Parameters'!$C$103 -> 0 | G32: ='Techno Economic Parameters'!$C$103 -> 0 | H32: ='Techno Economic Parameters'!$C$103 -> 0 | I32: ='Techno Economic Parameters'!$C$103 -> 0
B33: Income from Silage Making Unit | C33: ='Techno Economic Parameters'!$C$102 -> 0 | D33: ='Techno Economic Parameters'!$C$102 -> 0 | E33: ='Techno Economic Parameters'!$C$102 -> 0 | F33: ='Techno Economic Parameters'!$C$102 -> 0 | G33: ='Techno Economic Parameters'!$C$102 -> 0 | H33: ='Techno Economic Parameters'!$C$102 -> 0 | I33: ='Techno Economic Parameters'!$C$102 -> 0
B35: Total Income | C35: =SUM(C27:C34) -> 1105600 | D35: =SUM(D27:D34) -> 1372000 | E35: =SUM(E27:E34) -> 1372000 | F35: =SUM(F27:F34) -> 1372000 | G35: =SUM(G27:G34) -> 1372000 | H35: =SUM(H27:H34) -> 1372000 | I35: =SUM(I27:I34) -> 1372000
B37: Net Income | C37: =C35-C24 -> 449401.72 | D37: =D35-D24 -> 696891.98 | E37: =E35-E24 -> 717136.93 | F37: =F35-F24 -> 739836.79 | G37: =G35-G24 -> 765289.22 | H37: =H35-H24 -> 793828.01 | I37: =I35-I24 -> 825827.36

Sheet Cash flow
C2: CASH FLOW STATEMENT
C4: I Year | D4: II Year | E4: III Year | F4: IV Year | G4: V Year | H4: VI Year | I4: VII Year
B5: Total Expenditure | C5: ='Expenditure Income '!C24 -> 656198.28 | D5: ='Expenditure Income '!D24 -> 675108.02 | E5: ='Expenditure Income '!E24 -> 654863.07 | F5: ='Expenditure Income '!F24 -> 632163.21 | G5: ='Expenditure Income '!G24 -> 606710.78 | H5: ='Expenditure Income '!H24 -> 578171.99 | I5: ='Expenditure Income '!I24 -> 546172.64
B6: Total Revenue | C6: ='Expenditure Income '!C35 -> 1105600 | D6: ='Expenditure Income '!D35 -> 1372000 | E6: ='Expenditure Income '!E35 -> 1372000 | F6: ='Expenditure Income '!F35 -> 1372000 | G6: ='Expenditure Income '!G35 -> 1372000 | H6: ='Expenditure Income '!H35 -> 1372000 | I6: ='Expenditure Income '!I35 -> 1372000
B7: Net Revenue | C7: =C6-C5 -> 449401.72 | D7: =D6-D5 -> 696891.98 | E7: =E6-E5 -> 717136.93 | F7: =F6-F5 -> 739836.79 | G7: =G6-G5 -> 765289.22 | H7: =H6-H5 -> 793828.01 | I7: =I6-I5 -> 825827.36
B10: Interest | C10: ='Expenditure Income '!C20 -> 174198.28 | D10: ='Expenditure Income '!D20 -> 156828.02 | E10: ='Expenditure Income '!E20 -> 136583.07 | F10: ='Expenditure Income '!F20 -> 113883.21 | G10: ='Expenditure Income '!G20 -> 88430.78 | H10: ='Expenditure Income '!H20 -> 59891.99 | I10: ='Expenditure Income '!I20 -> 27892.64
B11: Depreciation | C11: ='Expenditure Income '!C21+'Expenditure Income '!C22 -> 73500 | D11: ='Expenditure Income '!D21+'Expenditure Income '!D22 -> 65362.5 | E11: ='Expenditure Income '!E21+'Expenditure Income '!E22 -> 58156.875 | F11: ='Expenditure Income '!F21+'Expenditure Income '!F22 -> 51772.219 | G11: ='Expenditure Income '!G21+'Expenditure Income '!G22 -> 46111.373 | H11: ='Expenditure Income '!H21+'Expenditure Income '!H22 -> 41089.156 | I11: ='Expenditure Income '!I21+'Expenditure Income '!I22 -> 36630.823
B12: Total (INT + DEP) | C12: =SUM(C10:C11) -> 247698.28 | D12: =SUM(D10:D11) -> 222190.52 | E12: =SUM(E10:E11) -> 194739.94 | F12: =SUM(F10:F11) -> 165655.43 | G12: =SUM(G10:G11) -> 134542.15 | H12: =SUM(H10:H11) -> 100981.15 | I12: =SUM(I10:I11) -> 64523.463
B14: Total Expenditure Without DEP+ INT | C14: =C5-C12 -> 408500 | D14: =D5-D12 -> 452917.5 | E14: =E5-E12 -> 460123.12 | F14: =F5-F12 -> 466507.78 | G14: =G5-G12 -> 472168.63 | H14: =H5-H12 -> 477190.84 | I14: =I5-I12 -> 481649.18
B15: Net Revenue After Dep and Int | C15: =C6-(C5-C12) -> 697100 | D15: =D6-(D5-D12) -> 919082.5 | E15: =E6-(E5-E12) -> 911876.88 | F15: =F6-(F5-F12) -> 905492.22 | G15: =G6-(G5-G12) -> 899831.37 | H15: =H6-(H5-H12) -> 894809.16 | I15: =I6-(I5-I12) -> 890350.82

Sheet Repayment
D2: REPAYMENT SCHEDULE
C4: Loan Amount | D4: =Investment!C55 -> 1551920
C5: Rate of Interest per annum | D5: ='Techno Economic Parameters'!C53 -> 11.5 | E5: =D5/12 -> 0.95833333 | F5: per month
C6: Term of loan in Years | D6: ='Techno Economic Parameters'!C54 -> 7 | E6: =D6*12 -> 84 | F6: months
C7: Payment due per year | D7: =(D$5%*$D$4)/(1-1/(1+D$5%)^D6) -> 334679.38
C8: Payment due per month | D8: =ROUND(((D5%/12*D$4))/(1-1/(1+(D$5%/12))^(D$6*12)),0) -> 26982
B9: MONTH | C9: PAYMENT DUE | D9: PRINCIPAL | E9: INTEREST | F9: BALANCE
F10: =D4 -> 1551920
B11: =IF(B10>=D6*12,"",B10+1) -> 1 | C11: =E11 -> 14872.57 | D11: 0 | E11: =IF(B11="","",ROUND(E5%*F10,2)) -> 14872.57 | F11: =IF(B11="","",F10-D11) -> 1551920
B12: =IF(B11>=D6*12,"",B11+1) -> 2 | C12: =E12 -> 14872.57 | D12: 0 | E12: =IF(B12="","",ROUND(E5%*F11,2)) -> 14872.57 | F12: =IF(B12="","",F11-D12) -> 1551920
B13: =IF(B12>=D6*12,"",B12+1) -> 3 | C13: =E13 -> 14872.57 | D13: 0 | E13: =IF(B13="","",ROUND(E5%*F12,2)) -> 14872.57 | F13: =IF(B13="","",F12-D13) -> 1551920
B14: =IF(B13>=D6*12,"",B13+1) -> 4 | C14: =IF(B14="","",IF(OR(B14=E6,D8>ROUND((1+E5%)*F13,2)),ROUND((1+E5%)*F13,2),D8)) -> 26982 | D14: =IF(B14="","",C14-E14) -> 12109.43 | E14: =IF(B14="","",ROUND(E5%*F13,2)) -> 14872.57 | F14: =IF(B14="","",F13-D14) -> 1539810.6
B15: =IF(B14>=D6*12,"",B14+1) -> 5 | C15: =IF(B15="","",IF(OR(B15=E6,D8>ROUND((1+E5%)*F14,2)),ROUND((1+E5%)*F14,2),D8)) -> 26982 | D15: =IF(B15="","",C15-E15) -> 12225.48 | E15: =IF(B15="","",ROUND(E5%*F14,2)) -> 14756.52 | F15: =IF(B15="","",F14-D15) -> 1527585.1
B16: =IF(B15>=D6*12,"",B15+1) -> 6 | C16: =IF(B16="","",IF(OR(B16=E6,D8>ROUND((1+E5%)*F15,2)),ROUND((1+E5%)*F15,2),D8)) -> 26982 | D16: =IF(B16="","",C16-E16) -> 12342.64 | E16: =IF(B16="","",ROUND(E5%*F15,2)) -> 14639.36 | F16: =IF(B16="","",F15-D16) -> 1515242.5
B17: =IF(B16>=D6*12,"",B16+1) -> 7 | C17: =IF(B17="","",IF(OR(B17=E6,D8>ROUND((1+E5%)*F16,2)),ROUND((1+E5%)*F16,2),D8)) -> 26982 | D17: =IF(B17="","",C17-E17) -> 12460.93 | E17: =IF(B17="","",ROUND(E5%*F16,2)) -> 14521.07 | F17: =IF(B17="","",F16-D17) -> 1502781.5
B18: =IF(B17>=D6*12,"",B17+1) -> 8 | C18: =IF(B18="","",IF(OR(B18=E6,D8>ROUND((1+E5%)*F17,2)),ROUND((1+E5%)*F17,2),D8)) -> 26982 | D18: =IF(B18="","",C18-E18) -> 12580.34 | E18: =IF(B18="","",ROUND(E5%*F17,2)) -> 14401.66 | F18: =IF(B18="","",F17-D18) -> 1490201.2
B19: =IF(B18>=D6*12,"",B18+1) -> 9 | C19: =IF(B19="","",IF(OR(B19=E6,D8>ROUND((1+E5%)*F18,2)),ROUND((1+E5%)*F18,2),D8)) -> 26982 | D19: =IF(B19="","",C19-E19) -> 12700.91 | E19: =IF(B19="","",ROUND(E5%*F18,2)) -> 14281.09 | F19: =IF(B19="","",F18-D19) -> 1477500.3
B20: =IF(B19>=D6*12,"",B19+1) -> 10 | C20: =IF(B20="","",IF(OR(B20=E6,D8>ROUND((1+E5%)*F19,2)),ROUND((1+E5%)*F19,2),D8)) -> 26982 | D20: =IF(B20="","",C20-E20) -> 12822.62 | E20: =IF(B20="","",ROUND(E5%*F19,2)) -> 14159.38 | F20: =IF(B20="","",F19-D20) -> 1464677.7
B21: =IF(B20>=D6*12,"",B20+1) -> 11 | C21: =IF(B21="","",IF(OR(B21=E6,D8>ROUND((1+E5%)*F20,2)),ROUND((1+E5%)*F20,2),D8)) -> 26982 | D21: =IF(B21="","",C21-E21) -> 12945.51 | E21: =IF(B21="","",ROUND(E5%*F20,2)) -> 14036.49 | F21: =IF(B21="","",F20-D21) -> 1451732.1
B22: =IF(B21>=D6*12,"",B21+1) -> 12 | C22: =IF(B22="","",IF(OR(B22=E6,D8>ROUND((1+E5%)*F21,2)),ROUND((1+E5%)*F21,2),D8)) -> 26982 | D22: =IF(B22="","",C22-E22) -> 13069.57 | E22: =IF(B22="","",ROUND(E5%*F21,2)) -> 13912.43 | F22: =IF(B22="","",F21-D22) -> 1438662.6
B23: =IF(B22>=D6*12,"",B22+1) -> 13 | C23: =IF(B23="","",IF(OR(B23=E6,D8>ROUND((1+E5%)*F22,2)),ROUND((1+E5%)*F22,2),D8)) -> 26982 | D23: =IF(B23="","",C23-E23) -> 13194.82 | E23: =IF(B23="","",ROUND(E5%*F22,2)) -> 13787.18 | F23: =IF(B23="","",F22-D23) -> 1425467.8
B24: =IF(B23>=D6*12,"",B23+1) -> 14 | C24: =IF(B24="","",IF(OR(B24=E6,D8>ROUND((1+E5%)*F23,2)),ROUND((1+E5%)*F23,2),D8)) -> 26982 | D24: =IF(B24="","",C24-E24) -> 13321.27 | E24: =IF(B24="","",ROUND(E5%*F23,2)) -> 13660.73 | F24: =IF(B24="","",F23-D24) -> 1412146.5
B25: =IF(B24>=D6*12,"",B24+1) -> 15 | C25: =IF(B25="","",IF(OR(B25=E6,D8>ROUND((1+E5%)*F24,2)),ROUND((1+E5%)*F24,2),D8)) -> 26982 | D25: =IF(B25="","",C25-E25) -> 13448.93 | E25: =IF(B25="","",ROUND(E5%*F24,2)) -> 13533.07 | F25: =IF(B25="","",F24-D25) -> 1398697.6
B26: =IF(B25>=D6*12,"",B25+1) -> 16 | C26: =IF(B26="","",IF(OR(B26=E6,D8>ROUND((1+E5%)*F25,2)),ROUND((1+E5%)*F25,2),D8)) -> 26982 | D26: =IF(B26="","",C26-E26) -> 13577.82 | E26: =IF(B26="","",ROUND(E5%*F25,2)) -> 13404.18 | F26: =IF(B26="","",F25-D26) -> 1385119.7
B27: =IF(B26>=D6*12,"",B26+1) -> 17 | C27: =IF(B27="","",IF(OR(B27=E6,D8>ROUND((1+E5%)*F26,2)),ROUND((1+E5%)*F26,2),D8)) -> 26982 | D27: =IF(B27="","",C27-E27) -> 13707.94 | E27: =IF(B27="","",ROUND(E5%*F26,2)) -> 13274.06 | F27: =IF(B27="","",F26-D27) -> 1371411.8
B28: =IF(B27>=D6*12,"",B27+1) -> 18 | C28: =IF(B28="","",IF(OR(B28=E6,D8>ROUND((1+E5%)*F27,2)),ROUND((1+E5%)*F27,2),D8)) -> 26982 | D28: =IF(B28="","",C28-E28) -> 13839.3 | E28: =IF(B28="","",ROUND(E5%*F27,2)) -> 13142.7 | F28: =IF(B28="","",F27-D28) -> 1357572.5
B29: =IF(B28>=D6*12,"",B28+1) -> 19 | C29: =IF(B29="","",IF(OR(B29=E6,D8>ROUND((1+E5%)*F28,2)),ROUND((1+E5%)*F28,2),D8)) -> 26982 | D29: =IF(B29="","",C29-E29) -> 13971.93 | E29: =IF(B29="","",ROUND(E5%*F28,2)) -> 13010.07 | F29: =IF(B29="","",F28-D29) -> 1343600.6
B30: =IF(B29>=D6*12,"",B29+1) -> 20 | C30: =IF(B30="","",IF(OR(B30=E6,D8>ROUND((1+E5%)*F29,2)),ROUND((1+E5%)*F29,2),D8)) -> 26982 | D30: =IF(B30="","",C30-E30) -> 14105.83 | E30: =IF(B30="","",ROUND(E5%*F29,2)) -> 12876.17 | F30: =IF(B30="","",F29-D30) -> 1329494.7
B31: =IF(B30>=D6*12,"",B30+1) -> 21 | C31: =IF(B31="","",IF(OR(B31=E6,D8>ROUND((1+E5%)*F30,2)),ROUND((1+E5%)*F30,2),D8)) -> 26982 | D31: =IF(B31="","",C31-E31) -> 14241.01 | E31: =IF(B31="","",ROUND(E5%*F30,2)) -> 12740.99 | F31: =IF(B31="","",F30-D31) -> 1315253.7
B32: =IF(B31>=D6*12,"",B31+1) -> 22 | C32: =IF(B32="","",IF(OR(B32=E6,D8>ROUND((1+E5%)*F31,2)),ROUND((1+E5%)*F31,2),D8)) -> 26982 | D32: =IF(B32="","",C32-E32) -> 14377.49 | E32: =IF(B32="","",ROUND(E5%*F31,2)) -> 12604.51 | F32: =IF(B32="","",F31-D32) -> 1300876.2
B33: =IF(B32>=D6*12,"",B32+1) -> 23 | C33: =IF(B33="","",IF(OR(B33=E6,D8>ROUND((1+E5%)*F32,2)),ROUND((1+E5%)*F32,2),D8)) -> 26982 | D33: =IF(B33="","",C33-E33) -> 14515.27 | E33: =IF(B33="","",ROUND(E5%*F32,2)) -> 12466.73 | F33: =IF(B33="","",F32-D33) -> 1286361
B34: =IF(B33>=D6*12,"",B33+1) -> 24 | C34: =IF(B34="","",IF(OR(B34=E6,D8>ROUND((1+E5%)*F33,2)),ROUND((1+E5%)*F33,2),D8)) -> 26982 | D34: =IF(B34="","",C34-E34) -> 14654.37 | E34: =IF(B34="","",ROUND(E5%*F33,2)) -> 12327.63 | F34: =IF(B34="","",F33-D34) -> 1271706.6
B35: =IF(B34>=D6*12,"",B34+1) -> 25 | C35: =IF(B35="","",IF(OR(B35=E6,D8>ROUND((1+E5%)*F34,2)),ROUND((1+E5%)*F34,2),D8)) -> 26982 | D35: =IF(B35="","",C35-E35) -> 14794.81 | E35: =IF(B35="","",ROUND(E5%*F34,2)) -> 12187.19 | F35: =IF(B35="","",F34-D35) -> 1256911.8
B36: =IF(B35>=D6*12,"",B35+1) -> 26 | C36: =IF(B36="","",IF(OR(B36=E6,D8>ROUND((1+E5%)*F35,2)),ROUND((1+E5%)*F35,2),D8)) -> 26982 | D36: =IF(B36="","",C36-E36) -> 14936.6 | E36: =IF(B36="","",ROUND(E5%*F35,2)) -> 12045.4 | F36: =IF(B36="","",F35-D36) -> 1241975.2
B37: =IF(B36>=D6*12,"",B36+1) -> 27 | C37: =IF(B37="","",IF(OR(B37=E6,D8>ROUND((1+E5%)*F36,2)),ROUND((1+E5%)*F36,2),D8)) -> 26982 | D37: =IF(B37="","",C37-E37) -> 15079.74 | E37: =IF(B37="","",ROUND(E5%*F36,2)) -> 11902.26 | F37: =IF(B37="","",F36-D37) -> 1226895.4
B38: =IF(B37>=D6*12,"",B37+1) -> 28 | C38: =IF(B38="","",IF(OR(B38=E6,D8>ROUND((1+E5%)*F37,2)),ROUND((1+E5%)*F37,2),D8)) -> 26982 | D38: =IF(B38="","",C38-E38) -> 15224.25 | E38: =IF(B38="","",ROUND(E5%*F37,2)) -> 11757.75 | F38: =IF(B38="","",F37-D38) -> 1211671.2
B39: =IF(B38>=D6*12,"",B38+1) -> 29 | C39: =IF(B39="","",IF(OR(B39=E6,D8>ROUND((1+E5%)*F38,2)),ROUND((1+E5%)*F38,2),D8)) -> 26982 | D39: =IF(B39="","",C39-E39) -> 15370.15 | E39: =IF(B39="","",ROUND(E5%*F38,2)) -> 11611.85 | F39: =IF(B39="","",F38-D39) -> 1196301
B40: =IF(B39>=D6*12,"",B39+1) -> 30 | C40: =IF(B40="","",IF(OR(B40=E6,D8>ROUND((1+E5%)*F39,2)),ROUND((1+E5%)*F39,2),D8)) -> 26982 | D40: =IF(B40="","",C40-E40) -> 15517.45 | E40: =IF(B40="","",ROUND(E5%*F39,2)) -> 11464.55 | F40: =IF(B40="","",F39-D40) -> 1180783.6
B41: =IF(B40>=D6*12,"",B40+1) -> 31 | C41: =IF(B41="","",IF(OR(B41=E6,D8>ROUND((1+E5%)*F40,2)),ROUND((1+E5%)*F40,2),D8)) -> 26982 | D41: =IF(B41="","",C41-E41) -> 15666.16 | E41: =IF(B41="","",ROUND(E5%*F40,2)) -> 11315.84 | F41: =IF(B41="","",F40-D41) -> 1165117.4
B42: =IF(B41>=D6*12,"",B41+1) -> 32 | C42: =IF(B42="","",IF(OR(B42=E6,D8>ROUND((1+E5%)*F41,2)),ROUND((1+E5%)*F41,2),D8)) -> 26982 | D42: =IF(B42="","",C42-E42) -> 15816.29 | E42: =IF(B42="","",ROUND(E5%*F41,2)) -> 11165.71 | F42: =IF(B42="","",F41-D42) -> 1149301.1
...

Sheet Depreciation
D1: DEPRECIATION
C2: Building | E2: Equipment | H2: Depreciation: Decline in value by usage or wear and tear. Buildings 10 % , Equipments 15%
A3: Year | B3: Beginning Value | C3: Rate of Dep. | D3: End Value | E3: Beginning Value | F3: Rate of Dep. | G3: End Value
A4: 1 | B4: =Investment!C7+Investment!C8+Investment!C9+Investment!C10 -> 577500 | C4: =B4*'Techno Economic Parameters'!C77% -> 57750 | D4: =B4-C4 -> 519750 | E4: =Investment!C11+Investment!C12+Investment!C13+Investment!C14+Investment!C15+Investment!C16+Investment!C17+Investment!C18+Investment!C19 -> 105000 | F4: =E4*'Techno Economic Parameters'!C78% -> 15750 | G4: =E4-F4 -> 89250
A5: 2 | B5: =D4 -> 519750 | C5: =B5*'Techno Economic Parameters'!C77% -> 51975 | D5: =B5-C5 -> 467775 | E5: =G4 -> 89250 | F5: =E5*'Techno Economic Parameters'!C78% -> 13387.5 | G5: =E5-F5 -> 75862.5
A6: 3 | B6: =D5 -> 467775 | C6: =B6*'Techno Economic Parameters'!C77% -> 46777.5 | D6: =B6-C6 -> 420997.5 | E6: =G5 -> 75862.5 | F6: =E6*'Techno Economic Parameters'!C78% -> 11379.375 | G6: =E6-F6 -> 64483.125
A7: 4 | B7: =D6 -> 420997.5 | C7: =B7*'Techno Economic Parameters'!C77% -> 42099.75 | D7: =B7-C7 -> 378897.75 | E7: =G6 -> 64483.125 | F7: =E7*'Techno Economic Parameters'!C78% -> 9672.4688 | G7: =E7-F7 -> 54810.656
A8: 5 | B8: =D7 -> 378897.75 | C8: =B8*'Techno Economic Parameters'!C77% -> 37889.775 | D8: =B8-C8 -> 341007.97 | E8: =G7 -> 54810.656 | F8: =E8*'Techno Economic Parameters'!C78% -> 8221.5984 | G8: =E8-F8 -> 46589.058
A9: 6 | B9: =D8 -> 341007.97 | C9: =B9*'Techno Economic Parameters'!C77% -> 34100.798 | D9: =B9-C9 -> 306907.18 | E9: =G8 -> 46589.058 | F9: =E9*'Techno Economic Parameters'!C78% -> 6988.3587 | G9: =E9-F9 -> 39600.699
A10: 7 | B10: =D9 -> 306907.18 | C10: =B10*'Techno Economic Parameters'!C77% -> 30690.718 | D10: =B10-C10 -> 276216.46 | E10: =G9 -> 39600.699 | F10: =E10*'Techno Economic Parameters'!C78% -> 5940.1049 | G10: =E10-F10 -> 33660.594

Sheet Financial Analysis
D2: FINANCIAL ANALYSIS OF THE PROJECT
B3: Net Present Worth and Benefit Cost Ratio
B5: Year | C5: Expenditure | D5: Revenue | E5: Discount Factor | F5: PWof Expenditure | G5: PW of Benefit
B6: 1 | C6: ='Cash flow'!C5 -> 656198.28 | D6: ='Cash flow'!C6 -> 1105600 | E6: =1/((1+'Techno Economic Parameters'!$C$53%)^'Financial Analysis'!B6) -> 0.89686099 | F6: =C6*E6 -> 588518.64 | G6: =E6*D6 -> 991569.51
B7: 2 | C7: ='Cash flow'!D5 -> 675108.02 | D7: ='Cash flow'!D6 -> 1372000 | E7: =1/((1+'Techno Economic Parameters'!$C$53%)^'Financial Analysis'!B7) -> 0.80435963 | F7: =C7*E7 -> 543029.64 | G7: =E7*D7 -> 1103581.4
B8: 3 | C8: ='Cash flow'!E5 -> 654863.07 | D8: ='Cash flow'!E6 -> 1372000 | E8: =1/((1+'Techno Economic Parameters'!$C$53%)^'Financial Analysis'!B8) -> 0.72139877 | F8: =C8*E8 -> 472417.41 | G8: =E8*D8 -> 989759.11
B9: 4 | C9: ='Cash flow'!F5 -> 632163.21 | D9: ='Cash flow'!F6 -> 1372000 | E9: =1/((1+'Techno Economic Parameters'!$C$53%)^'Financial Analysis'!B9) -> 0.64699441 | F9: =C9*E9 -> 409006.07 | G9: =E9*D9 -> 887676.33
B10: 5 | C10: ='Cash flow'!G5 -> 606710.78 | D10: ='Cash flow'!G6 -> 1372000 | E10: =1/((1+'Techno Economic Parameters'!$C$53%)^'Financial Analysis'!B10) -> 0.58026405 | F10: =C10*E10 -> 352052.45 | G10: =E10*D10 -> 796122.27
B11: 6 | C11: ='Cash flow'!H5 -> 578171.99 | D11: ='Cash flow'!H7 -> 793828.01 | E11: =1/((1+'Techno Economic Parameters'!$C$53%)^'Financial Analysis'!B11) -> 0.52041619 | F11: =C11*E11 -> 300890.06 | G11: =E11*D11 -> 413120.95
B12: 7 | C12: ='Cash flow'!I5 -> 546172.64 | D12: ='Cash flow'!I6 -> 1372000 | E12: =1/((1+'Techno Economic Parameters'!$C$53%)^'Financial Analysis'!B12) -> 0.46674097 | F12: =C12*E12 -> 254921.15 | G12: =E12*D12 -> 640368.62
E14: Total | F14: =SUM(F6:F13) -> 2920835.4 | G14: =SUM(G6:G13) -> 5822198.2
E15: NPW | F15: =G14-F14 -> 2901362.8
E16: BCR | F16: =G14/F14 -> 1.9933332
B17: Internal Rate of Return
B18: Year | C18: INB | D18: PV of Lower IR | E18: DF Higher IR | F18: PV of Higher IR
B19: 1 | C19: =D6-C6 -> 449401.72 | D19: =C19*E6 -> 403050.87 | E19: =1/(((1+(('Techno Economic Parameters'!$C$53+20)%))^'Financial Analysis'!B6)) -> 0.76045627 | F19: =C19*E19 -> 341750.36
B20: 2 | C20: =D7-C7 -> 696891.98 | D20: =C20*E7 -> 560551.77 | E20: =1/(((1+(('Techno Economic Parameters'!$C$53+20)%))^'Financial Analysis'!B7)) -> 0.57829374 | F20: =C20*E20 -> 403008.27
B21: 3 | C21: =D8-C8 -> 717136.93 | D21: =C21*E8 -> 517341.7 | E21: =1/(((1+(('Techno Economic Parameters'!$C$53+20)%))^'Financial Analysis'!B8)) -> 0.43976711 | F21: =C21*E21 -> 315373.23
B22: 4 | C22: =D9-C9 -> 739836.79 | D22: =C22*E9 -> 478670.27 | E22: =1/(((1+(('Techno Economic Parameters'!$C$53+20)%))^'Financial Analysis'!B9)) -> 0.33442365 | F22: =C22*E22 -> 247418.92
B23: 5 | C23: =D10-C10 -> 765289.22 | D23: =C23*E10 -> 444069.82 | E23: =1/(((1+(('Techno Economic Parameters'!$C$53+20)%))^'Financial Analysis'!B10)) -> 0.25431457 | F23: =C23*E23 -> 194624.2
B24: 6 | C24: =D11-C11 -> 215656.02 | D24: =C24*E11 -> 112230.88 | E24: =1/(((1+(('Techno Economic Parameters'!$C$53+20)%))^'Financial Analysis'!B11)) -> 0.19339511 | F24: =C24*E24 -> 41706.819
B25: 7 | C25: =D12-C12 -> 825827.36 | D25: =C25*E12 -> 385447.47 | E25: =1/(((1+(('Techno Economic Parameters'!$C$53+20)%))^'Financial Analysis'!B12)) -> 0.14706852 | F25: =C25*E25 -> 121453.21
C27: Total | D27: =SUM(D19:D26) -> 2901362.8 | F27: =SUM(F19:F26) -> 1665335
D28: IRR | E28: =('Techno Economic Parameters'!C53+(((('Techno Economic Parameters'!C53+20)-'Techno Economic Parameters'!C53)*(('Financial Analysis'!D27/('Financial Analysis'!D27+'Financial Analysis'!F27)))))) -> 24.206612 | F28: %
B29: Debt Service Coverage Ratio
B30: Year | C30: Net Income | D30: Total Debt | E30: DSCR Vaue
B31: 1 | C31: ='Cash flow'!C15 -> 697100 | D31: =SUM(Repayment!D11:D22)+'Expenditure Income '!$C$20 -> 287455.71 | E31: =C31/D31 -> 2.4250692 | F31: VIABLE OF THE PROJECT
B32: 2 | C32: ='Cash flow'!D15 -> 919082.5 | D32: =SUM(Repayment!D23:D34)+'Expenditure Income '!$D$20 -> 323784 | E32: =C32/D32 -> 2.8385668 | F32: NPW | G32: Positive
B33: 3 | C33: ='Cash flow'!E15 -> 911876.88 | D33: =SUM(Repayment!D35:D46)+'Expenditure Income '!$E$20 -> 323784 | E33: =C33/D33 -> 2.8163123 | F33: BCR | G33: More than one
B34: 4 | C34: ='Cash flow'!F15 -> 905492.22 | D34: =SUM(Repayment!D47:D58)+'Expenditure Income '!$F$20 -> 323784 | E34: =C34/D34 -> 2.7965935 | F34: IRR | G34: More than the lower interest rate
B35: 5 | C35: ='Cash flow'!G15 -> 899831.37 | D35: =SUM(Repayment!D59:D70)+'Expenditure Income '!$G$20 -> 323784 | E35: =C35/D35 -> 2.7791101 | F35: DSCR | G35: Above two
B36: 6 | C36: ='Cash flow'!H15 -> 894809.16 | D36: =SUM(Repayment!D71:D82)+'Expenditure Income '!$H$20 -> 323784 | E36: =C36/D36 -> 2.7635991
B37: 7 | C37: ='Cash flow'!I15 -> 890350.82 | D37: =SUM(Repayment!D83:D94)+'Expenditure Income '!$I$20 -> 403252.28 | E37: =C37/D37 -> 2.2079251
D38: Average DSCR | E38: =SUM(E31:E37)/'Techno Economic Parameters'!C54 -> 2.6610251
